<?xml version="1.0" ?>
<!-- =================================================================================== -->
<!-- |    This document was autogenerated by xacro from /home/thib/CollaborativeBaxter/src/ridgeback_baxter/ridgeback_baxter_description/urdf/ridgeback_baxter.urdf.xacro | -->
<!-- |    EDITING THIS FILE BY HAND IS NOT RECOMMENDED                                 | -->
<!-- =================================================================================== -->
<robot name="ridgeback_baxter" xmlns:xacro="http://ros.org/wiki/xacro">
  <material name="dark_grey">
    <color rgba="0.2 0.2 0.2 1.0"/>
  </material>
  <material name="light_grey">
    <color rgba="0.4 0.4 0.4 1.0"/>
  </material>
  <material name="red">
    <color rgba="0.8 0.0 0.0 1.0"/>
  </material>
  <material name="white">
    <color rgba="0.9 0.9 0.9 1.0"/>
  </material>
  <material name="yellow">
    <color rgba="0.8 0.8 0.0 1.0"/>
  </material>
  <material name="black">
    <color rgba="0.15 0.15 0.15 1.0"/>
  </material>
  <link name="front_rocker_link">
    <visual>
      <origin rpy="1.57079632679 0 1.57079632679" xyz="0 0 0"/>
      <geometry>
        <mesh filename="package://ridgeback_description/meshes/rocker.stl"/>
      </geometry>
      <material name="black"/>
    </visual>
    <inertial>
      <origin rpy="1.57079632679 0 1.57079632679" xyz="0 0 0"/>
      <mass value="10.267"/>
      <inertia ixx="0.0288" ixy="2.20484e-6" ixz="-1.3145e-5" iyy="0.4324" iyz="1.8944e-3" izz="0.4130"/>
    </inertial>
  </link>
  <joint name="front_rocker" type="revolute">
    <parent link="axle_link"/>
    <child link="front_rocker_link"/>
    <origin rpy="0 0 0" xyz="0.319 0 0"/>
    <axis xyz="1 0 0"/>
    <limit effort="0" lower="-0.08726" upper="0.08726" velocity="0"/>
  </joint>
  <link name="front_left_wheel_link">
    <visual>
      <origin rpy="1.57079632679 0 0" xyz="0 0 0"/>
      <geometry>
        <mesh filename="package://ridgeback_description/meshes/wheel.stl"/>
      </geometry>
      <material name="black"/>
    </visual>
    <collision>
      <origin rpy="1.57079632679 0 0" xyz="0 0 0"/>
      <geometry>
        <cylinder length="0.079" radius="0.0759"/>
      </geometry>
    </collision>
    <inertial>
      <origin rpy="0 0 0" xyz="0 0 0"/>
      <mass value="2.3"/>
      <inertia ixx="3.3212e-3" ixy="0" ixz="0" iyy="6.6424e-3" iyz="0" izz="3.3212e-3"/>
    </inertial>
  </link>
  <joint name="front_left_wheel" type="continuous">
    <parent link="front_rocker_link"/>
    <child link="front_left_wheel_link"/>
    <origin rpy="0 0 0" xyz="0 0.2755 0"/>
    <axis xyz="0 1 0"/>
  </joint>
  <transmission name="front_wheel_trans">
    <type>transmission_interface/SimpleTransmission</type>
    <joint name="front_left_wheel">
      <hardwareInterface>hardware_interface/VelocityJointInterface</hardwareInterface>
    </joint>
    <actuator name="front_left_actuator">
      <mechanicalReduction>1</mechanicalReduction>
    </actuator>
  </transmission>
  <link name="front_right_wheel_link">
    <visual>
      <origin rpy="1.57079632679 0 0" xyz="0 0 0"/>
      <geometry>
        <mesh filename="package://ridgeback_description/meshes/wheel.stl"/>
      </geometry>
      <material name="black"/>
    </visual>
    <collision>
      <origin rpy="1.57079632679 0 0" xyz="0 0 0"/>
      <geometry>
        <cylinder length="0.079" radius="0.0759"/>
      </geometry>
    </collision>
    <inertial>
      <origin rpy="0 0 0" xyz="0 0 0"/>
      <mass value="2.3"/>
      <inertia ixx="3.3212e-3" ixy="0" ixz="0" iyy="6.6424e-3" iyz="0" izz="3.3212e-3"/>
    </inertial>
  </link>
  <joint name="front_right_wheel" type="continuous">
    <parent link="front_rocker_link"/>
    <child link="front_right_wheel_link"/>
    <origin rpy="0 0 0" xyz="0 -0.2755 0"/>
    <axis xyz="0 1 0"/>
  </joint>
  <transmission name="front_wheel_trans">
    <type>transmission_interface/SimpleTransmission</type>
    <joint name="front_right_wheel">
      <hardwareInterface>hardware_interface/VelocityJointInterface</hardwareInterface>
    </joint>
    <actuator name="front_right_actuator">
      <mechanicalReduction>1</mechanicalReduction>
    </actuator>
  </transmission>
  <link name="rear_rocker_link">
    <visual>
      <origin rpy="1.57079632679 0 1.57079632679" xyz="0 0 0"/>
      <geometry>
        <mesh filename="package://ridgeback_description/meshes/rocker.stl"/>
      </geometry>
      <material name="black"/>
    </visual>
    <inertial>
      <origin rpy="1.57079632679 0 1.57079632679" xyz="0 0 0"/>
      <mass value="10.267"/>
      <inertia ixx="0.0288" ixy="2.20484e-6" ixz="-1.3145e-5" iyy="0.4324" iyz="1.8944e-3" izz="0.4130"/>
    </inertial>
  </link>
  <joint name="rear_rocker" type="fixed">
    <parent link="axle_link"/>
    <child link="rear_rocker_link"/>
    <origin rpy="0 0 0" xyz="-0.319 0 0"/>
    <axis xyz="1 0 0"/>
    <limit effort="0" velocity="0"/>
  </joint>
  <link name="rear_left_wheel_link">
    <visual>
      <origin rpy="1.57079632679 0 0" xyz="0 0 0"/>
      <geometry>
        <mesh filename="package://ridgeback_description/meshes/wheel.stl"/>
      </geometry>
      <material name="black"/>
    </visual>
    <collision>
      <origin rpy="1.57079632679 0 0" xyz="0 0 0"/>
      <geometry>
        <cylinder length="0.079" radius="0.0759"/>
      </geometry>
    </collision>
    <inertial>
      <origin rpy="0 0 0" xyz="0 0 0"/>
      <mass value="2.3"/>
      <inertia ixx="3.3212e-3" ixy="0" ixz="0" iyy="6.6424e-3" iyz="0" izz="3.3212e-3"/>
    </inertial>
  </link>
  <joint name="rear_left_wheel" type="continuous">
    <parent link="rear_rocker_link"/>
    <child link="rear_left_wheel_link"/>
    <origin rpy="0 0 0" xyz="0 0.2755 0"/>
    <axis xyz="0 1 0"/>
  </joint>
  <transmission name="rear_wheel_trans">
    <type>transmission_interface/SimpleTransmission</type>
    <joint name="rear_left_wheel">
      <hardwareInterface>hardware_interface/VelocityJointInterface</hardwareInterface>
    </joint>
    <actuator name="rear_left_actuator">
      <mechanicalReduction>1</mechanicalReduction>
    </actuator>
  </transmission>
  <link name="rear_right_wheel_link">
    <visual>
      <origin rpy="1.57079632679 0 0" xyz="0 0 0"/>
      <geometry>
        <mesh filename="package://ridgeback_description/meshes/wheel.stl"/>
      </geometry>
      <material name="black"/>
    </visual>
    <collision>
      <origin rpy="1.57079632679 0 0" xyz="0 0 0"/>
      <geometry>
        <cylinder length="0.079" radius="0.0759"/>
      </geometry>
    </collision>
    <inertial>
      <origin rpy="0 0 0" xyz="0 0 0"/>
      <mass value="2.3"/>
      <inertia ixx="3.3212e-3" ixy="0" ixz="0" iyy="6.6424e-3" iyz="0" izz="3.3212e-3"/>
    </inertial>
  </link>
  <joint name="rear_right_wheel" type="continuous">
    <parent link="rear_rocker_link"/>
    <child link="rear_right_wheel_link"/>
    <origin rpy="0 0 0" xyz="0 -0.2755 0"/>
    <axis xyz="0 1 0"/>
  </joint>
  <transmission name="rear_wheel_trans">
    <type>transmission_interface/SimpleTransmission</type>
    <joint name="rear_right_wheel">
      <hardwareInterface>hardware_interface/VelocityJointInterface</hardwareInterface>
    </joint>
    <actuator name="rear_right_actuator">
      <mechanicalReduction>1</mechanicalReduction>
    </actuator>
  </transmission>
  <link name="base_link"/>
  <joint name="base_link_joint" type="fixed">
    <origin rpy="0 0 0" xyz="0 0 0"/>
    <parent link="base_link"/>
    <child link="chassis_link"/>
  </joint>
  <link name="chassis_link">
    <visual>
      <origin rpy="0 0 0" xyz="0 0 0"/>
      <geometry>
        <mesh filename="package://ridgeback_description/meshes/body.stl"/>
      </geometry>
      <material name="black"/>
    </visual>
    <collision>
      <origin xyz="0 0 0"/>
      <geometry>
        <mesh filename="package://ridgeback_description/meshes/body-collision.stl"/>
      </geometry>
    </collision>
    <inertial>
      <origin rpy="1.57079632679 0 1.57079632679" xyz="0.012 0.002 0.067"/>
      <mass value="165.304"/>
      <inertia ixx="4.4744" ixy="0.03098" ixz="0.003647" iyy="7.1624" iyz="0.1228" izz="4.6155"/>
    </inertial>
  </link>
  <joint name="right_side_cover_link_joint" type="fixed">
    <origin rpy="0 0 0" xyz="0 0 0"/>
    <parent link="chassis_link"/>
    <child link="right_side_cover_link"/>
  </joint>
  <joint name="left_side_cover_link_joint" type="fixed">
    <origin rpy="0 0 0" xyz="0 0 0"/>
    <parent link="chassis_link"/>
    <child link="left_side_cover_link"/>
  </joint>
  <link name="left_side_cover_link">
    <visual>
      <origin rpy="0 0 3.14159265359" xyz="0 0 0"/>
      <geometry>
        <mesh filename="package://ridgeback_description/meshes/side-cover.stl"/>
      </geometry>
      <material name="yellow"/>
    </visual>
  </link>
  <link name="right_side_cover_link">
    <visual>
      <origin rpy="0 0 0" xyz="0 0 0"/>
      <geometry>
        <mesh filename="package://ridgeback_description/meshes/side-cover.stl"/>
      </geometry>
      <material name="yellow"/>
    </visual>
  </link>
  <joint name="front_cover_link_joint" type="fixed">
    <origin rpy="0 0 0" xyz="0 0 0"/>
    <parent link="chassis_link"/>
    <child link="front_cover_link"/>
  </joint>
  <link name="front_cover_link">
    <visual>
      <origin rpy="0 0 0" xyz="0 0 0"/>
      <geometry>
        <mesh filename="package://ridgeback_description/meshes/end-cover.stl"/>
      </geometry>
      <material name="black"/>
    </visual>
  </link>
  <joint name="rear_cover_link_joint" type="fixed">
    <origin rpy="0 0 0" xyz="0 0 0"/>
    <parent link="chassis_link"/>
    <child link="rear_cover_link"/>
  </joint>
  <link name="rear_cover_link">
    <visual>
      <origin rpy="0 0 3.14159265359" xyz="0 0 0"/>
      <geometry>
        <mesh filename="package://ridgeback_description/meshes/end-cover.stl"/>
      </geometry>
      <material name="black"/>
    </visual>
  </link>
  <joint name="front_lights_link_joint" type="fixed">
    <origin rpy="0 0 0" xyz="0 0 0"/>
    <parent link="chassis_link"/>
    <child link="front_lights_link"/>
  </joint>
  <joint name="rear_lights_link_joint" type="fixed">
    <origin rpy="0 0 0" xyz="0 0 0"/>
    <parent link="chassis_link"/>
    <child link="rear_lights_link"/>
  </joint>
  <link name="front_lights_link">
    <visual>
      <origin rpy="0 0 0" xyz="0 0 0"/>
      <geometry>
        <mesh filename="package://ridgeback_description/meshes/lights.stl"/>
      </geometry>
      <material name="white"/>
    </visual>
  </link>
  <link name="rear_lights_link">
    <visual>
      <origin rpy="0 0 3.14159265359" xyz="0 0 0"/>
      <geometry>
        <mesh filename="package://ridgeback_description/meshes/lights.stl"/>
      </geometry>
      <material name="red"/>
    </visual>
  </link>
  <joint name="top_link_joint" type="fixed">
    <origin rpy="0 0 0" xyz="0 0 0"/>
    <parent link="chassis_link"/>
    <child link="top_link"/>
  </joint>
  <link name="top_link">
    <visual>
      <origin rpy="0 0 0" xyz="0 0 0"/>
      <geometry>
        <mesh filename="package://ridgeback_description/meshes/top.stl"/>
      </geometry>
      <material name="black"/>
    </visual>
    <collision>
      <origin rpy="0 0 0" xyz="0 0 0"/>
      <geometry>
        <mesh filename="package://ridgeback_description/meshes/top.stl"/>
      </geometry>
    </collision>
  </link>
  <joint name="axle_joint" type="fixed">
    <origin rpy="0 0 0" xyz="0 0 0.05"/>
    <parent link="chassis_link"/>
    <child link="axle_link"/>
  </joint>
  <link name="axle_link">
    <visual>
      <origin rpy="0 1.57079632679 0" xyz="0 0 0"/>
      <geometry>
        <mesh filename="package://ridgeback_description/meshes/axle.stl"/>
      </geometry>
      <material name="black"/>
    </visual>
  </link>
  <link name="imu_link">
    <inertial>
      <mass value="0.001"/>
      <origin rpy="0 0 0" xyz="0 0 0"/>
      <inertia ixx="1e-09" ixy="0.0" ixz="0.0" iyy="1e-09" iyz="0.0" izz="1e-09"/>
    </inertial>
  </link>
  <joint name="imu_joint" type="fixed">
    <parent link="chassis_link"/>
    <child link="imu_link"/>
    <origin rpy="0 0 0" xyz="0.2085 -0.2902 0.1681"/>
  </joint>
  <link name="mid_mount"/>
  <joint name="mid_mount_joint" type="fixed">
    <parent link="base_link"/>
    <child link="mid_mount"/>
    <origin rpy="0 0 0" xyz="0 0 0.28"/>
  </joint>
  <gazebo>
    <plugin filename="libgazebo_ros_control.so" name="gazebo_ros_control">
      <robotNamespace>/</robotNamespace>
      <legacyModeNS>true</legacyModeNS>
    </plugin>
    <plugin filename="libridgeback_ros_force_based_move.so" name="ridgeback_ros_force_based_move">
      <robotNamespace>/</robotNamespace>
      <commandTopic>cmd_vel</commandTopic>
      <odometryTopic>odom</odometryTopic>
      <odometryFrame>odom</odometryFrame>
      <odometryRate>25.0</odometryRate>
      <robotBaseFrame>base_link</robotBaseFrame>
      <cmdVelTimeOut>0.25</cmdVelTimeOut>
      <!-- Don't publish a transform: the controller does it. -->
      <publishOdometryTf>0</publishOdometryTf>
      <yaw_velocity_p_gain>500.0</yaw_velocity_p_gain>
      <x_velocity_p_gain>10000.0</x_velocity_p_gain>
      <y_velocity_p_gain>10000.0</y_velocity_p_gain>
    </plugin>
    <plugin filename="libhector_gazebo_ros_imu.so" name="imu_controller">
      <robotNamespace>/</robotNamespace>
      <updateRate>50.0</updateRate>
      <bodyName>imu_link</bodyName>
      <topicName>imu/data</topicName>
      <accelDrift>0.005 0.005 0.005</accelDrift>
      <accelGaussianNoise>0.005 0.005 0.005</accelGaussianNoise>
      <rateDrift>0.00005 0.00005 0.00005</rateDrift>
      <rateGaussianNoise>0.00005 0.00005 0.00005</rateGaussianNoise>
      <headingDrift>0.005</headingDrift>
      <headingGaussianNoise>0.005</headingGaussianNoise>
    </plugin>
    <plugin filename="libgazebo_ros_joint_state_publisher.so" name="gazebo_ros_joint_state_publisher">
      <jointName>front_rocker</jointName>
      <robotNamespace>/</robotNamespace>
      <updateRate>50.0</updateRate>
    </plugin>
  </gazebo>
  <!-- All static links get collapsed down to base_link in Gazebo, so that's
       the one to apply the colour to (in Gazebo 5+). -->
  <gazebo reference="base_link">
    <material>Gazebo/DarkGrey</material>
    <gravity>true</gravity>
  </gazebo>
  <!-- Individual link colouring still needed in Gazebo 2.x -->
  <gazebo reference="chassis_link">
    <material>Gazebo/DarkGrey</material>
  </gazebo>
  <gazebo reference="top_link">
    <material>Gazebo/DarkGrey</material>
  </gazebo>
  <gazebo reference="left_side_cover_link">
    <material>Gazebo/Yellow</material>
  </gazebo>
  <gazebo reference="right_side_cover_link">
    <material>Gazebo/Yellow</material>
  </gazebo>
  <gazebo reference="front_cover_link">
    <material>Gazebo/DarkGrey</material>
  </gazebo>
  <gazebo reference="rear_cover_link">
    <material>Gazebo/DarkGrey</material>
  </gazebo>
  <gazebo reference="front_lights_link">
    <material>Gazebo/White</material>
  </gazebo>
  <gazebo reference="rear_lights_link">
    <material>Gazebo/Red</material>
  </gazebo>
  <gazebo reference="front_rocker_link">
    <material>Gazebo/DarkGrey</material>
  </gazebo>
  <gazebo reference="rear_rocker_link">
    <material>Gazebo/DarkGrey</material>
  </gazebo>
  <gazebo reference="axle_link">
    <material>Gazebo/DarkGrey</material>
  </gazebo>
  <!-- Wheel friction to zero, as movement is handled by applying forces at
       the body level. -->
  <gazebo reference="front_left_wheel_link">
    <material>Gazebo/DarkGrey</material>
    <mu1>0.0</mu1>
    <mu2>0.0</mu2>
  </gazebo>
  <gazebo reference="front_right_wheel_link">
    <material>Gazebo/DarkGrey</material>
    <mu1>0.0</mu1>
    <mu2>0.0</mu2>
  </gazebo>
  <gazebo reference="rear_left_wheel_link">
    <material>Gazebo/DarkGrey</material>
    <mu1>0.0</mu1>
    <mu2>0.0</mu2>
  </gazebo>
  <gazebo reference="rear_right_wheel_link">
    <material>Gazebo/DarkGrey</material>
    <mu1>0.0</mu1>
    <mu2>0.0</mu2>
  </gazebo>
  <!-- This is an wheel-level solution to possibly revisit at a future date. -->
  <!--<gazebo>
    <plugin name="mecanum_gazebo" filename="libmecanum_force_plugin.so">
      <wheelJointName>front_left_wheel</wheelJointName>
      <forceScaleFactor>1</forceScaleFactor>
    </plugin>
    <plugin name="mecanum_gazebo" filename="libmecanum_force_plugin.so">
      <wheelJointName>front_right_wheel</wheelJointName>
      <forceScaleFactor>-1</forceScaleFactor>
    </plugin>
    <plugin name="mecanum_gazebo" filename="libmecanum_force_plugin.so">
      <wheelJointName>rear_left_wheel</wheelJointName>
      <forceScaleFactor>-1</forceScaleFactor>
    </plugin>
    <plugin name="mecanum_gazebo" filename="libmecanum_force_plugin.so">
      <wheelJointName>rear_right_wheel</wheelJointName>
      <forceScaleFactor>1</forceScaleFactor>
    </plugin>
  </gazebo> -->
  <!--
    As you add to this URDF, please be aware that both the robot and
    simulation include it. You must retain compatibility with all of
    the following launch files:

    ridgeback_viz/launch/view_model.launch
    ridgeback_gazebo/launch/ridgeback_world.launch
    ridgeback_base/launch/base.launch
  -->
  <joint name="front_laser_joint" type="fixed">
    <origin rpy="0 0 0.0" xyz="0.3932 0 0.2330"/>
    <parent link="chassis_link"/>
    <child link="front_laser"/>
  </joint>
  <link name="front_laser">
    <inertial>
      <mass value="0.130"/>
      <origin xyz="0 0 0"/>
      <inertia ixx="8.01666346e-05" ixy="0.0" ixz="0.0" iyy="8.01666346e-05" iyz="0.0" izz="5.4166645e-05"/>
    </inertial>
    <visual>
      <origin rpy="0 0 0" xyz="0 0 0"/>
      <geometry>
        <!-- Origin of this mesh is the focal point of the LIDAR. -->
        <mesh filename="package://ridgeback_description/meshes/ust-10lx.stl"/>
      </geometry>
      <material name="dark_grey"/>
    </visual>
    <collision>
      <origin rpy="0 0 0" xyz="0 0 -0.0122"/>
      <geometry>
        <box size="0.05 0.05 0.07"/>
      </geometry>
    </collision>
  </link>
  <gazebo reference="front_laser">
    <turnGravityOff>false</turnGravityOff>
    <sensor name="front_laser" type="ray">
      <pose>0 0 0 0 0 0</pose>
      <visualize>false</visualize>
      <update_rate>50</update_rate>
      <ray>
        <scan>
          <horizontal>
            <samples>720</samples>
            <resolution>1</resolution>
            <min_angle>-2.35619</min_angle>
            <max_angle>2.35619</max_angle>
          </horizontal>
        </scan>
        <range>
          <min>0.20</min>
          <max>10.0</max>
          <resolution>0.01</resolution>
        </range>
        <noise>
          <type>gaussian</type>
          <mean>0.0</mean>
          <stddev>0.001</stddev>
        </noise>
      </ray>
      <plugin filename="libgazebo_ros_laser.so" name="gazebo_ros_laser">
        <topicName>front/scan</topicName>
        <frameName>front_laser</frameName>
        <hokuyoMinIntensity>101</hokuyoMinIntensity>
      </plugin>
    </sensor>
    <material>Gazebo/DarkGrey</material>
  </gazebo>
  <joint name="rear_laser_joint" type="fixed">
    <origin rpy="0 0 3.14159265359" xyz="-0.3932 0 0.2330"/>
    <parent link="chassis_link"/>
    <child link="rear_laser"/>
  </joint>
  <link name="rear_laser">
    <inertial>
      <mass value="0.130"/>
      <origin xyz="0 0 0"/>
      <inertia ixx="8.01666346e-05" ixy="0.0" ixz="0.0" iyy="8.01666346e-05" iyz="0.0" izz="5.4166645e-05"/>
    </inertial>
    <visual>
      <origin rpy="0 0 0" xyz="0 0 0"/>
      <geometry>
        <!-- Origin of this mesh is the focal point of the LIDAR. -->
        <mesh filename="package://ridgeback_description/meshes/ust-10lx.stl"/>
      </geometry>
      <material name="dark_grey"/>
    </visual>
    <collision>
      <origin rpy="0 0 0" xyz="0 0 -0.0122"/>
      <geometry>
        <box size="0.05 0.05 0.07"/>
      </geometry>
    </collision>
  </link>
  <gazebo reference="rear_laser">
    <turnGravityOff>false</turnGravityOff>
    <sensor name="rear_laser" type="ray">
      <pose>0 0 0 0 0 0</pose>
      <visualize>false</visualize>
      <update_rate>50</update_rate>
      <ray>
        <scan>
          <horizontal>
            <samples>720</samples>
            <resolution>1</resolution>
            <min_angle>-2.35619</min_angle>
            <max_angle>2.35619</max_angle>
          </horizontal>
        </scan>
        <range>
          <min>0.20</min>
          <max>10.0</max>
          <resolution>0.01</resolution>
        </range>
        <noise>
          <type>gaussian</type>
          <mean>0.0</mean>
          <stddev>0.001</stddev>
        </noise>
      </ray>
      <plugin filename="libgazebo_ros_laser.so" name="gazebo_ros_laser">
        <topicName>rear/scan</topicName>
        <frameName>rear_laser</frameName>
        <hokuyoMinIntensity>101</hokuyoMinIntensity>
      </plugin>
    </sensor>
    <material>Gazebo/DarkGrey</material>
  </gazebo>
  <!-- This file is a placeholder which is included by default from
       ridgeback.urdf.xacro. If a robot is being customized and requires
       additional URDF, set the RIDGEBACK_URDF_EXTRAS environment variable
       to the full path of the file you would like included. -->
  <link name="base">
  </link>
  <link name="torso">
    <visual>
      <origin rpy="0 0 0" xyz="0 0 0"/>
      <geometry>
        <mesh filename="package://baxter_description/meshes/torso/base_link.DAE"/>
      </geometry>
      <material name="darkgray">
        <color rgba=".2 .2 .2 1"/>
      </material>
    </visual>
    <collision>
      <origin rpy="0 0 0" xyz="0 0 0"/>
      <geometry>
        <mesh filename="package://baxter_description/meshes/torso/base_link_collision.DAE"/>
      </geometry>
    </collision>
    <inertial>
      <origin rpy="0 0 0" xyz="0.000000 0.000000 0.000000"/>
      <mass value="35.336455"/>
      <inertia ixx="1.849155" ixy="-0.000354" ixz="-0.154188" iyy="1.662671" iyz="0.003292" izz="0.802239"/>
    </inertial>
  </link>
  <link name="left_torso_itb">
    <inertial>
      <origin rpy="0 0 0" xyz="0.000000 0.000000 0.000000"/>
      <mass value="0.0001"/>
      <inertia ixx="1e-08" ixy="0" ixz="0" iyy="1e-08" iyz="0" izz="1e-08"/>
    </inertial>
  </link>
  <link name="right_torso_itb">
    <inertial>
      <origin rpy="0 0 0" xyz="0.000000 0.000000 0.000000"/>
      <mass value="0.0001"/>
      <inertia ixx="1e-08" ixy="0" ixz="0" iyy="1e-08" iyz="0" izz="1e-08"/>
    </inertial>
  </link>
  <link name="head">
    <visual>
      <origin rpy="0 0 0" xyz="0 0 .00953"/>
      <geometry>
        <mesh filename="package://baxter_description/meshes/head/H0.DAE"/>
      </geometry>
      <material name="darkgray">
        <color rgba=".2 .2 .2 1"/>
      </material>
    </visual>
    <collision>
      <origin rpy="0 0 0" xyz="0.0 0 0.0"/>
      <geometry>
        <sphere radius="0.001"/>
      </geometry>
    </collision>
    <inertial>
      <origin rpy="0 0 0" xyz="0 0 0"/>
      <mass value="0.547767"/>
      <inertia ixx="0.004641" ixy="0.000159" ixz="0.000242" iyy="0.003295" iyz="-0.001324" izz="0.003415"/>
    </inertial>
  </link>
  <link name="sonar_ring">
    <visual>
      <origin rpy="0 0 0" xyz="-.0347 0 .00953"/>
      <geometry>
        <cylinder length="0.01" radius="0.085"/>
      </geometry>
      <material name="darkgray">
        <color rgba=".2 .2 .2 1"/>
      </material>
    </visual>
    <collision>
      <origin rpy="0 0 0" xyz="0.0 0 0.0"/>
      <geometry>
        <sphere radius="0.001"/>
      </geometry>
    </collision>
    <inertial>
      <origin rpy="0 0 0" xyz="0 0 0"/>
      <mass value="0.0001"/>
      <inertia ixx="1e-08" ixy="0" ixz="0" iyy="1e-08" iyz="0" izz="1e-08"/>
    </inertial>
  </link>
  <link name="screen">
    <visual>
      <origin rpy="0 -1.57079632679 0" xyz="0 -.00953 -.0347"/>
      <geometry>
        <mesh filename="package://baxter_description/meshes/head/H1.DAE"/>
      </geometry>
      <material name="darkred">
        <color rgba=".5 .1 .1 1"/>
      </material>
    </visual>
    <collision>
      <origin rpy="0 0 0" xyz="0.0 0 0.0"/>
      <geometry>
        <sphere radius="0.001"/>
      </geometry>
    </collision>
    <inertial>
      <origin rpy="0 0 0" xyz="0 0 0"/>
      <mass value="0.440171"/>
      <inertia ixx="0.004006" ixy="0.000230" ixz="0.000002" iyy="0.002800" iyz="0.000029" izz="0.001509"/>
    </inertial>
  </link>
  <link name="display">
    <visual>
      <origin rpy="0.2617993877991494 0 0" xyz="0 0 0"/>
      <geometry>
        <box size="0.218 0.16 0.001"/>
      </geometry>
      <material name="black">
        <color rgba="0 0 0 1"/>
      </material>
    </visual>
    <inertial>
      <origin rpy="0 0 0" xyz="0 0 0"/>
      <mass value="0.0001"/>
      <inertia ixx="1e-08" ixy="0" ixz="0" iyy="1e-08" iyz="0" izz="1e-08"/>
    </inertial>
  </link>
  <link name="head_camera">
    <inertial>
      <origin rpy="0 0 0" xyz="0 0 0"/>
      <mass value="0.0001"/>
      <inertia ixx="1e-08" ixy="0" ixz="0" iyy="1e-08" iyz="0" izz="1e-08"/>
    </inertial>
  </link>
  <link name="dummyhead1">
    <inertial>
      <origin rpy="0 0 0" xyz="0 0 0"/>
      <mass value="0.0001"/>
      <inertia ixx="1e-08" ixy="0" ixz="0" iyy="1e-08" iyz="0" izz="1e-08"/>
    </inertial>
  </link>
  <link name="collision_head_link_1">
    <visual>
      <origin rpy="0 0 0" xyz="0 0 0"/>
      <geometry>
        <sphere radius="0.001"/>
      </geometry>
      <material name="red">
        <color rgba="0.8 0.3 0.3 0.3"/>
      </material>
    </visual>
    <collision>
      <origin rpy="0 0 0.0" xyz="-0.07 -0.04 0.0"/>
      <geometry>
        <sphere radius="0.22"/>
      </geometry>
    </collision>
    <inertial>
      <origin rpy="0 0 0" xyz="0 0 0"/>
      <mass value="0.0001"/>
      <inertia ixx="1e-08" ixy="0" ixz="0" iyy="1e-08" iyz="0" izz="1e-08"/>
    </inertial>
  </link>
  <link name="collision_head_link_2">
    <visual>
      <origin rpy="0 0 0" xyz="0 0 0"/>
      <geometry>
        <sphere radius="0.001"/>
      </geometry>
      <material name="red">
        <color rgba="0.8 0.3 0.3 0.3"/>
      </material>
    </visual>
    <collision>
      <origin rpy="0 0 0" xyz="-0.07 0.04 0.00"/>
      <geometry>
        <sphere radius="0.22"/>
      </geometry>
    </collision>
    <inertial>
      <origin rpy="0 0 0" xyz="0 0 0"/>
      <mass value="0.0001"/>
      <inertia ixx="1e-08" ixy="0" ixz="0" iyy="1e-08" iyz="0" izz="1e-08"/>
    </inertial>
  </link>
  <joint name="collision_head_1" type="fixed">
    <origin rpy="0 0 0" xyz="0.11 0 0.75"/>
    <parent link="base"/>
    <child link="collision_head_link_1"/>
  </joint>
  <joint name="collision_head_2" type="fixed">
    <origin rpy="0 0 0" xyz="0.11 0 0.75"/>
    <parent link="base"/>
    <child link="collision_head_link_2"/>
  </joint>
  <joint name="dummy" type="fixed">
    <origin rpy="0 0 0" xyz="0 0 0"/>
    <parent link="head"/>
    <child link="dummyhead1"/>
  </joint>
  <joint name="torso_t0" type="fixed">
    <origin rpy="0 0 0" xyz="0 0 0"/>
    <parent link="base"/>
    <child link="torso"/>
    <limit effort="50000" lower="-3.01" upper="3.01" velocity="10000"/>
  </joint>
  <joint name="left_torso_itb_fixed" type="fixed">
    <origin rpy="-1.57079632679 3.1415 0" xyz="-0.08897 0.15593 0.389125"/>
    <parent link="torso"/>
    <child link="left_torso_itb"/>
  </joint>
  <joint name="right_torso_itb_fixed" type="fixed">
    <origin rpy="1.57079632679 0 0" xyz="-0.08897 -0.15593 0.389125"/>
    <parent link="torso"/>
    <child link="right_torso_itb"/>
  </joint>
  <joint name="head_pan" type="revolute">
    <origin rpy="0 0 0" xyz="0.06 0 0.686"/>
    <axis xyz="0 0 1"/>
    <parent link="torso"/>
    <child link="head"/>
    <limit effort="50000" lower="-1.3963" upper="1.3963" velocity="10000"/>
    <dynamics damping="0.7" friction="0.0"/>
  </joint>
  <joint name="head_nod" type="fixed">
    <origin rpy="1.75057 0 1.57079632679" xyz=".1227 0 0"/>
    <parent link="head"/>
    <child link="screen"/>
  </joint>
  <joint name="head_camera" type="fixed">
    <origin rpy="1.75057 0 1.57079632679" xyz="0.12839 0 0.06368"/>
    <parent link="head"/>
    <child link="head_camera"/>
  </joint>
  <joint name="display_joint" type="fixed">
    <origin rpy="0 0 0" xyz="0.0 -0.016 0.0"/>
    <parent link="screen"/>
    <child link="display"/>
  </joint>
  <joint name="sonar_s0" type="fixed">
    <origin rpy="0 0 0" xyz="0.0947 0 .817"/>
    <axis xyz="0 0 1"/>
    <parent link="torso"/>
    <child link="sonar_ring"/>
  </joint>
  <link name="right_arm_mount">
    <!-- all defaults -->
    <inertial>
      <origin rpy="0 0 0" xyz="0 0 0"/>
      <mass value="0.0001"/>
      <inertia ixx="1e-08" ixy="0" ixz="0" iyy="1e-08" iyz="0" izz="1e-08"/>
    </inertial>
  </link>
  <link name="right_upper_shoulder">
    <visual>
      <origin rpy="0 0 0" xyz="0 0 0"/>
      <geometry>
        <mesh filename="package://baxter_description/meshes/upper_shoulder/S0.DAE"/>
      </geometry>
      <material name="darkred">
        <color rgba=".5 .1 .1 1"/>
      </material>
    </visual>
    <collision>
      <origin rpy="0 0 0" xyz="0 0 0.1361"/>
      <geometry>
        <cylinder length="0.2722" radius="0.06"/>
      </geometry>
    </collision>
    <inertial>
      <origin rpy="0 0 0" xyz="0.01783 0.00086 0.19127"/>
      <mass value="5.70044"/>
      <inertia ixx="0.04709102262" ixy="0.00012787556" ixz="0.00614870039" iyy="0.03766976455" iyz="0.00078086899" izz="0.03595988478"/>
    </inertial>
  </link>
  <link name="right_lower_shoulder">
    <visual>
      <origin rpy="0 0 0" xyz="0 0 0"/>
      <geometry>
        <mesh filename="package://baxter_description/meshes/lower_shoulder/S1.DAE"/>
      </geometry>
      <material name="darkred">
        <color rgba=".5 .1 .1 1"/>
      </material>
    </visual>
    <collision>
      <origin rpy="0 0 0" xyz="0 0 0"/>
      <geometry>
        <cylinder length="0.12" radius="0.06"/>
      </geometry>
    </collision>
    <inertial>
      <origin rpy="0 0 0" xyz="0.06845 0.00269 -0.00529"/>
      <mass value="3.22698"/>
      <inertia ixx="0.01175209419" ixy="-0.00030096398" ixz="0.00207675762" iyy="0.0278859752" iyz="-0.00018821993" izz="0.02078749298"/>
    </inertial>
  </link>
  <link name="right_upper_elbow">
    <visual>
      <origin rpy="0 0 0" xyz="0 0 0"/>
      <geometry>
        <mesh filename="package://baxter_description/meshes/upper_elbow/E0.DAE"/>
      </geometry>
      <material name="darkred">
        <color rgba=".5 .1 .1 1"/>
      </material>
    </visual>
    <collision>
      <origin rpy="0 0 0" xyz="0 0 -0.0535"/>
      <geometry>
        <cylinder length="0.107" radius="0.06"/>
      </geometry>
    </collision>
    <inertial>
      <origin rpy="0 0 0" xyz="-0.00276 0.00132 0.18086"/>
      <mass value="4.31272"/>
      <inertia ixx="0.02661733557" ixy="0.00029270634" ixz="0.00392189887" iyy="0.02844355207" iyz="0.0010838933" izz="0.01248008322"/>
    </inertial>
  </link>
  <link name="right_upper_elbow_visual">
    <collision>
      <origin rpy="0 0 0" xyz="0 0 0.1365"/>
      <geometry>
        <cylinder length="0.273" radius="0.06"/>
      </geometry>
    </collision>
    <inertial>
      <origin rpy="0 0 0" xyz="0 0 0"/>
      <mass value="0.0001"/>
      <inertia ixx="1e-08" ixy="0" ixz="0" iyy="1e-08" iyz="0" izz="1e-08"/>
    </inertial>
  </link>
  <link name="right_lower_elbow">
    <visual>
      <origin rpy="0 0 0" xyz="0 0 0"/>
      <geometry>
        <mesh filename="package://baxter_description/meshes/lower_elbow/E1.DAE"/>
      </geometry>
      <material name="darkred">
        <color rgba=".5 .1 .1 1"/>
      </material>
    </visual>
    <collision>
      <origin rpy="0 0 0" xyz="0.0 0.0 0.0"/>
      <geometry>
        <cylinder length="0.10" radius="0.06"/>
      </geometry>
    </collision>
    <inertial>
      <origin rpy="0 0 0" xyz="0.02611 0.00159 -0.01117"/>
      <mass value="2.07206"/>
      <inertia ixx="0.00711582686" ixy="0.00036036173" ixz="0.0007459496" iyy="0.01318227876" iyz="-0.00019663418" izz="0.00926852064"/>
    </inertial>
  </link>
  <link name="right_upper_forearm">
    <visual>
      <origin rpy="0 0 0" xyz="0 0 0"/>
      <geometry>
        <mesh filename="package://baxter_description/meshes/upper_forearm/W0.DAE"/>
      </geometry>
      <material name="darkred">
        <color rgba=".5 .1 .1 1"/>
      </material>
    </visual>
    <collision>
      <origin rpy="0 0 0" xyz="0 0 -0.044"/>
      <geometry>
        <cylinder length="0.088" radius="0.06"/>
      </geometry>
    </collision>
    <inertial>
      <origin rpy="0 0 0" xyz="-0.00168 0.0046 0.13952"/>
      <mass value="2.24665"/>
      <inertia ixx="0.01667742825" ixy="0.00018403705" ixz="0.00018657629" iyy="0.01675457264" iyz="-0.00064732352" izz="0.0037463115"/>
    </inertial>
  </link>
  <link name="right_upper_forearm_visual">
    <collision>
      <origin rpy="0 0 0" xyz="0 0 0.136"/>
      <geometry>
        <cylinder length="0.272" radius="0.06"/>
      </geometry>
    </collision>
    <inertial>
      <origin rpy="0 0 0" xyz="0 0 0"/>
      <mass value="0.0001"/>
      <inertia ixx="1e-08" ixy="0" ixz="0" iyy="1e-08" iyz="0" izz="1e-08"/>
    </inertial>
  </link>
  <link name="right_arm_itb">
    <inertial>
      <origin rpy="0 0 0" xyz="0.000000 0.000000 0.000000"/>
      <mass value="0.0001"/>
      <inertia ixx="1e-08" ixy="0" ixz="0" iyy="1e-08" iyz="0" izz="1e-08"/>
    </inertial>
  </link>
  <link name="right_lower_forearm">
    <visual>
      <origin rpy="0 0 0" xyz="0 0 0"/>
      <geometry>
        <mesh filename="package://baxter_description/meshes/lower_forearm/W1.DAE"/>
      </geometry>
      <material name="darkred">
        <color rgba=".5 .1 .1 1"/>
      </material>
    </visual>
    <collision>
      <origin rpy="0 0 0" xyz="0 0 0"/>
      <geometry>
        <cylinder length="0.10" radius="0.06"/>
      </geometry>
    </collision>
    <inertial>
      <origin rpy="0 0 0" xyz="0.06041 0.00697 0.006"/>
      <mass value="1.60979"/>
      <inertia ixx="0.00387607152" ixy="-0.00044384784" ixz="-0.00021115038" iyy="0.00700537914" iyz="0.00015348067" izz="0.0055275524"/>
    </inertial>
  </link>
  <link name="right_wrist">
    <visual>
      <origin rpy="0 0 0" xyz="0 0 0"/>
      <geometry>
        <mesh filename="package://baxter_description/meshes/wrist/W2.DAE"/>
      </geometry>
      <material name="lightgrey">
        <color rgba=".1 .1 .1 1"/>
      </material>
    </visual>
    <collision>
      <origin rpy="0 0 0" xyz="0 0 0"/>
      <geometry>
        <cylinder length="0.165" radius="0.06"/>
      </geometry>
    </collision>
    <inertial>
      <origin rpy="0 0 0" xyz="0.00198 0.00125 0.01855"/>
      <mass value="0.35093"/>
      <inertia ixx="0.00025289155" ixy="0.00000575311" ixz="-0.00000159345" iyy="0.0002688601" iyz="-0.00000519818" izz="0.0003074118"/>
    </inertial>
  </link>
  <link name="right_hand">
    <collision>
      <origin rpy="0 0 0" xyz="0 0 -0.0232"/>
      <geometry>
        <cylinder length="0.0464" radius="0.04"/>
      </geometry>
    </collision>
    <inertial>
      <origin rpy="0 0 0" xyz="0.01093 0.00042 -0.01532"/>
      <mass value="0.19125"/>
      <inertia ixx="0.00017588" ixy="0.00000147073" ixz="0.0000243633" iyy="0.00021166377" iyz="0.00000172689" izz="0.00023745397"/>
    </inertial>
  </link>
  <link name="right_hand_camera">
    <visual>
      <origin rpy="0 0 0" xyz="0 0 0"/>
      <geometry>
        <cylinder length="0.01" radius="0.02"/>
      </geometry>
      <material name="blue">
        <color rgba="0 0 1 0.8"/>
      </material>
    </visual>
    <inertial>
      <origin rpy="0 0 0" xyz="0 0 0"/>
      <mass value="0.0001"/>
      <inertia ixx="1e-08" ixy="0" ixz="0" iyy="1e-08" iyz="0" izz="1e-08"/>
    </inertial>
  </link>
  <link name="right_hand_camera_axis">
    <inertial>
      <origin rpy="0 0 0" xyz="0 0 0"/>
      <mass value="0.0001"/>
      <inertia ixx="1e-08" ixy="0" ixz="0" iyy="1e-08" iyz="0" izz="1e-08"/>
    </inertial>
  </link>
  <link name="right_hand_range">
    <visual>
      <origin rpy="0 0 0" xyz="0 0 0"/>
      <geometry>
        <box size="0.005 .02 .005"/>
      </geometry>
      <material name="blue">
        <color rgba="0 0 1 0.8"/>
      </material>
    </visual>
    <inertial>
      <origin rpy="0 0 0" xyz="0 0 0"/>
      <mass value="0.0001"/>
      <inertia ixx="1e-08" ixy="0" ixz="0" iyy="1e-08" iyz="0" izz="1e-08"/>
    </inertial>
  </link>
  <link name="right_hand_accelerometer">
    <visual>
      <origin rpy="0 0 0" xyz="0 0 0"/>
      <geometry>
        <box size="0.01 0.01 0.01"/>
      </geometry>
      <material name="black">
        <color rgba="0 0 0 1"/>
      </material>
    </visual>
    <inertial>
      <origin rpy="0 0 0" xyz="0.000000 0.000000 0.000000"/>
      <mass value="0.0001"/>
      <inertia ixx="1e-08" ixy="0" ixz="0" iyy="1e-08" iyz="0" izz="1e-08"/>
    </inertial>
  </link>
  <joint name="right_torso_arm_mount" type="fixed">
    <origin rpy="0 0 -0.7854" xyz="0.024645 -0.219645 0.118588"/>
    <parent link="torso"/>
    <child link="right_arm_mount"/>
  </joint>
  <joint name="right_s0" type="revolute">
    <origin rpy="0 0 0" xyz="0.055695 0 0.011038"/>
    <axis xyz="0 0 1"/>
    <parent link="right_arm_mount"/>
    <child link="right_upper_shoulder"/>
    <limit effort="50.0" lower="-1.70167993878" upper="1.70167993878" velocity="1.5"/>
    <dynamics damping="0.7" friction="0.0"/>
  </joint>
  <joint name="right_s1" type="revolute">
    <origin rpy="-1.57079632679 0 0" xyz="0.069 0 0.27035"/>
    <axis xyz="0 0 1"/>
    <parent link="right_upper_shoulder"/>
    <child link="right_lower_shoulder"/>
    <limit effort="50.0" lower="-2.147" upper="1.047" velocity="1.5"/>
    <dynamics damping="0.7" friction="0.0"/>
  </joint>
  <joint name="right_e0" type="revolute">
    <origin rpy="1.57079632679 0 1.57079632679" xyz="0.102 0 0"/>
    <axis xyz="0 0 1"/>
    <parent link="right_lower_shoulder"/>
    <child link="right_upper_elbow"/>
    <limit effort="50.0" lower="-3.05417993878" upper="3.05417993878" velocity="1.5"/>
    <dynamics damping="0.7" friction="0.0"/>
  </joint>
  <joint name="right_e0_fixed" type="fixed">
    <origin rpy="1.57079632679 0 1.57079632679" xyz="0.107 0 0"/>
    <axis xyz="0 0 1"/>
    <parent link="right_lower_shoulder"/>
    <child link="right_upper_elbow_visual"/>
  </joint>
  <joint name="right_e1" type="revolute">
    <origin rpy="-1.57079632679 -1.57079632679 0" xyz="0.069 0 0.26242"/>
    <axis xyz="0 0 1"/>
    <parent link="right_upper_elbow"/>
    <child link="right_lower_elbow"/>
    <limit effort="50.0" lower="-0.05" upper="2.618" velocity="1.5"/>
    <dynamics damping="0.7" friction="0.0"/>
  </joint>
  <joint name="right_w0" type="revolute">
    <origin rpy="1.57079632679 0 1.57079632679" xyz="0.10359 0 0"/>
    <axis xyz="0 0 1"/>
    <parent link="right_lower_elbow"/>
    <child link="right_upper_forearm"/>
    <limit effort="15.0" lower="-3.059" upper="3.059" velocity="4.0"/>
    <dynamics damping="0.7" friction="0.0"/>
  </joint>
  <joint name="right_w0_fixed" type="fixed">
    <origin rpy="1.57079632679 0 1.57079632679" xyz="0.088 0 0"/>
    <axis xyz="0 0 1"/>
    <parent link="right_lower_elbow"/>
    <child link="right_upper_forearm_visual"/>
  </joint>
  <joint name="right_w0_to_itb_fixed" type="fixed">
    <origin rpy="-1.57079632679 0 1.57079632679" xyz="-0.0565 0 0.12"/>
    <axis xyz="0 0 1"/>
    <parent link="right_upper_forearm"/>
    <child link="right_arm_itb"/>
  </joint>
  <joint name="right_w1" type="revolute">
    <origin rpy="-1.57079632679 -1.57079632679 0" xyz="0.01 0 0.2707"/>
    <axis xyz="0 0 1"/>
    <parent link="right_upper_forearm"/>
    <child link="right_lower_forearm"/>
    <limit effort="15.0" lower="-1.57079632679" upper="2.094" velocity="4.0"/>
    <dynamics damping="0.7" friction="0.0"/>
  </joint>
  <joint name="right_w2" type="revolute">
    <origin rpy="1.57079632679 0 1.57079632679" xyz="0.115975 0 0"/>
    <axis xyz="0 0 1"/>
    <parent link="right_lower_forearm"/>
    <child link="right_wrist"/>
    <limit effort="15.0" lower="-3.059" upper="3.059" velocity="4.0"/>
    <dynamics damping="0.7" friction="0.0"/>
  </joint>
  <joint name="right_hand" type="fixed">
    <origin rpy="0 0 0" xyz="0 0 0.11355"/>
    <axis xyz="0 0 1"/>
    <parent link="right_wrist"/>
    <child link="right_hand"/>
  </joint>
  <joint name="right_hand_camera" type="fixed">
    <origin rpy="0 0 -1.57079633" xyz="0.03825 0.012 0.015355"/>
    <parent link="right_hand"/>
    <child link="right_hand_camera"/>
  </joint>
  <joint name="right_hand_camera_axis" type="fixed">
    <origin rpy="0 0 0" xyz="0.03825 0.012 0.015355"/>
    <parent link="right_hand"/>
    <child link="right_hand_camera_axis"/>
  </joint>
  <joint name="right_hand_range" type="fixed">
    <origin rpy="0 -1.57079632679 -1.57079632679" xyz="0.032 -0.020245 0.0288"/>
    <parent link="right_hand"/>
    <child link="right_hand_range"/>
  </joint>
  <joint name="right_hand_accelerometer" type="fixed">
    <origin rpy="0 0 0" xyz="0.00198 0.000133 -0.0146"/>
    <parent link="right_hand"/>
    <child link="right_hand_accelerometer"/>
  </joint>
  <link name="left_arm_mount">
    <!-- all defaults -->
    <inertial>
      <origin rpy="0 0 0" xyz="0 0 0"/>
      <mass value="0.0001"/>
      <inertia ixx="1e-08" ixy="0" ixz="0" iyy="1e-08" iyz="0" izz="1e-08"/>
    </inertial>
  </link>
  <link name="left_upper_shoulder">
    <visual>
      <origin rpy="0 0 0" xyz="0 0 0"/>
      <geometry>
        <mesh filename="package://baxter_description/meshes/upper_shoulder/S0.DAE"/>
      </geometry>
      <material name="darkred">
        <color rgba=".5 .1 .1 1"/>
      </material>
    </visual>
    <collision>
      <origin rpy="0 0 0" xyz="0 0 0.1361"/>
      <geometry>
        <cylinder length="0.2722" radius="0.06"/>
      </geometry>
    </collision>
    <inertial>
      <origin rpy="0 0 0" xyz="0.01783 0.00086 0.19127"/>
      <mass value="5.70044"/>
      <inertia ixx="0.04709102262" ixy="0.00012787556" ixz="0.00614870039" iyy="0.03766976455" iyz="0.00078086899" izz="0.03595988478"/>
    </inertial>
  </link>
  <link name="left_lower_shoulder">
    <visual>
      <origin rpy="0 0 0" xyz="0 0 0"/>
      <geometry>
        <mesh filename="package://baxter_description/meshes/lower_shoulder/S1.DAE"/>
      </geometry>
      <material name="darkred">
        <color rgba=".5 .1 .1 1"/>
      </material>
    </visual>
    <collision>
      <origin rpy="0 0 0" xyz="0 0 0"/>
      <geometry>
        <cylinder length="0.12" radius="0.06"/>
      </geometry>
    </collision>
    <inertial>
      <origin rpy="0 0 0" xyz="0.06845 0.00269 -0.00529"/>
      <mass value="3.22698"/>
      <inertia ixx="0.01175209419" ixy="-0.00030096398" ixz="0.00207675762" iyy="0.0278859752" iyz="-0.00018821993" izz="0.02078749298"/>
    </inertial>
  </link>
  <link name="left_upper_elbow">
    <visual>
      <origin rpy="0 0 0" xyz="0 0 0"/>
      <geometry>
        <mesh filename="package://baxter_description/meshes/upper_elbow/E0.DAE"/>
      </geometry>
      <material name="darkred">
        <color rgba=".5 .1 .1 1"/>
      </material>
    </visual>
    <collision>
      <origin rpy="0 0 0" xyz="0 0 -0.0535"/>
      <geometry>
        <cylinder length="0.107" radius="0.06"/>
      </geometry>
    </collision>
    <inertial>
      <origin rpy="0 0 0" xyz="-0.00276 0.00132 0.18086"/>
      <mass value="4.31272"/>
      <inertia ixx="0.02661733557" ixy="0.00029270634" ixz="0.00392189887" iyy="0.02844355207" iyz="0.0010838933" izz="0.01248008322"/>
    </inertial>
  </link>
  <link name="left_upper_elbow_visual">
    <collision>
      <origin rpy="0 0 0" xyz="0 0 0.1365"/>
      <geometry>
        <cylinder length="0.273" radius="0.06"/>
      </geometry>
    </collision>
    <inertial>
      <origin rpy="0 0 0" xyz="0 0 0"/>
      <mass value="0.0001"/>
      <inertia ixx="1e-08" ixy="0" ixz="0" iyy="1e-08" iyz="0" izz="1e-08"/>
    </inertial>
  </link>
  <link name="left_lower_elbow">
    <visual>
      <origin rpy="0 0 0" xyz="0 0 0"/>
      <geometry>
        <mesh filename="package://baxter_description/meshes/lower_elbow/E1.DAE"/>
      </geometry>
      <material name="darkred">
        <color rgba=".5 .1 .1 1"/>
      </material>
    </visual>
    <collision>
      <origin rpy="0 0 0" xyz="0.0 0.0 0.0"/>
      <geometry>
        <cylinder length="0.10" radius="0.06"/>
      </geometry>
    </collision>
    <inertial>
      <origin rpy="0 0 0" xyz="0.02611 0.00159 -0.01117"/>
      <mass value="2.07206"/>
      <inertia ixx="0.00711582686" ixy="0.00036036173" ixz="0.0007459496" iyy="0.01318227876" iyz="-0.00019663418" izz="0.00926852064"/>
    </inertial>
  </link>
  <link name="left_upper_forearm">
    <visual>
      <origin rpy="0 0 0" xyz="0 0 0"/>
      <geometry>
        <mesh filename="package://baxter_description/meshes/upper_forearm/W0.DAE"/>
      </geometry>
      <material name="darkred">
        <color rgba=".5 .1 .1 1"/>
      </material>
    </visual>
    <collision>
      <origin rpy="0 0 0" xyz="0 0 -0.044"/>
      <geometry>
        <cylinder length="0.088" radius="0.06"/>
      </geometry>
    </collision>
    <inertial>
      <origin rpy="0 0 0" xyz="-0.00168 0.0046 0.13952"/>
      <mass value="2.24665"/>
      <inertia ixx="0.01667742825" ixy="0.00018403705" ixz="0.00018657629" iyy="0.01675457264" iyz="-0.00064732352" izz="0.0037463115"/>
    </inertial>
  </link>
  <link name="left_upper_forearm_visual">
    <collision>
      <origin rpy="0 0 0" xyz="0 0 0.136"/>
      <geometry>
        <cylinder length="0.272" radius="0.06"/>
      </geometry>
    </collision>
    <inertial>
      <origin rpy="0 0 0" xyz="0 0 0"/>
      <mass value="0.0001"/>
      <inertia ixx="1e-08" ixy="0" ixz="0" iyy="1e-08" iyz="0" izz="1e-08"/>
    </inertial>
  </link>
  <link name="left_arm_itb">
    <inertial>
      <origin rpy="0 0 0" xyz="0.000000 0.000000 0.000000"/>
      <mass value="0.0001"/>
      <inertia ixx="1e-08" ixy="0" ixz="0" iyy="1e-08" iyz="0" izz="1e-08"/>
    </inertial>
  </link>
  <link name="left_lower_forearm">
    <visual>
      <origin rpy="0 0 0" xyz="0 0 0"/>
      <geometry>
        <mesh filename="package://baxter_description/meshes/lower_forearm/W1.DAE"/>
      </geometry>
      <material name="darkred">
        <color rgba=".5 .1 .1 1"/>
      </material>
    </visual>
    <collision>
      <origin rpy="0 0 0" xyz="0 0 0"/>
      <geometry>
        <cylinder length="0.10" radius="0.06"/>
      </geometry>
    </collision>
    <inertial>
      <origin rpy="0 0 0" xyz="0.06041 0.00697 0.006"/>
      <mass value="1.60979"/>
      <inertia ixx="0.00387607152" ixy="-0.00044384784" ixz="-0.00021115038" iyy="0.00700537914" iyz="0.00015348067" izz="0.0055275524"/>
    </inertial>
  </link>
  <link name="left_wrist">
    <visual>
      <origin rpy="0 0 0" xyz="0 0 0"/>
      <geometry>
        <mesh filename="package://baxter_description/meshes/wrist/W2.DAE"/>
      </geometry>
      <material name="lightgrey">
        <color rgba=".1 .1 .1 1"/>
      </material>
    </visual>
    <collision>
      <origin rpy="0 0 0" xyz="0 0 0"/>
      <geometry>
        <cylinder length="0.165" radius="0.06"/>
      </geometry>
    </collision>
    <inertial>
      <origin rpy="0 0 0" xyz="0.00198 0.00125 0.01855"/>
      <mass value="0.35093"/>
      <inertia ixx="0.00025289155" ixy="0.00000575311" ixz="-0.00000159345" iyy="0.0002688601" iyz="-0.00000519818" izz="0.0003074118"/>
    </inertial>
  </link>
  <link name="left_hand">
    <collision>
      <origin rpy="0 0 0" xyz="0 0 -0.0232"/>
      <geometry>
        <cylinder length="0.0464" radius="0.04"/>
      </geometry>
    </collision>
    <inertial>
      <origin rpy="0 0 0" xyz="0.01093 0.00042 -0.01532"/>
      <mass value="0.19125"/>
      <inertia ixx="0.00017588" ixy="0.00000147073" ixz="0.0000243633" iyy="0.00021166377" iyz="0.00000172689" izz="0.00023745397"/>
    </inertial>
  </link>
  <link name="left_hand_camera">
    <visual>
      <origin rpy="0 0 0" xyz="0 0 0"/>
      <geometry>
        <cylinder length="0.01" radius="0.02"/>
      </geometry>
      <material name="blue">
        <color rgba="0 0 1 0.8"/>
      </material>
    </visual>
    <inertial>
      <origin rpy="0 0 0" xyz="0 0 0"/>
      <mass value="0.0001"/>
      <inertia ixx="1e-08" ixy="0" ixz="0" iyy="1e-08" iyz="0" izz="1e-08"/>
    </inertial>
  </link>
  <link name="left_hand_camera_axis">
    <inertial>
      <origin rpy="0 0 0" xyz="0 0 0"/>
      <mass value="0.0001"/>
      <inertia ixx="1e-08" ixy="0" ixz="0" iyy="1e-08" iyz="0" izz="1e-08"/>
    </inertial>
  </link>
  <link name="left_hand_range">
    <visual>
      <origin rpy="0 0 0" xyz="0 0 0"/>
      <geometry>
        <box size="0.005 .02 .005"/>
      </geometry>
      <material name="blue">
        <color rgba="0 0 1 0.8"/>
      </material>
    </visual>
    <inertial>
      <origin rpy="0 0 0" xyz="0 0 0"/>
      <mass value="0.0001"/>
      <inertia ixx="1e-08" ixy="0" ixz="0" iyy="1e-08" iyz="0" izz="1e-08"/>
    </inertial>
  </link>
  <link name="left_hand_accelerometer">
    <visual>
      <origin rpy="0 0 0" xyz="0 0 0"/>
      <geometry>
        <box size="0.01 0.01 0.01"/>
      </geometry>
      <material name="black">
        <color rgba="0 0 0 1"/>
      </material>
    </visual>
    <inertial>
      <origin rpy="0 0 0" xyz="0.000000 0.000000 0.000000"/>
      <mass value="0.0001"/>
      <inertia ixx="1e-08" ixy="0" ixz="0" iyy="1e-08" iyz="0" izz="1e-08"/>
    </inertial>
  </link>
  <joint name="left_torso_arm_mount" type="fixed">
    <origin rpy="0 0 0.7854" xyz="0.024645 0.219645 0.118588"/>
    <parent link="torso"/>
    <child link="left_arm_mount"/>
  </joint>
  <joint name="left_s0" type="revolute">
    <origin rpy="0 0 0" xyz="0.055695 0 0.011038"/>
    <axis xyz="0 0 1"/>
    <parent link="left_arm_mount"/>
    <child link="left_upper_shoulder"/>
    <limit effort="50.0" lower="-1.70167993878" upper="1.70167993878" velocity="1.5"/>
    <dynamics damping="0.7" friction="0.0"/>
  </joint>
  <joint name="left_s1" type="revolute">
    <origin rpy="-1.57079632679 0 0" xyz="0.069 0 0.27035"/>
    <axis xyz="0 0 1"/>
    <parent link="left_upper_shoulder"/>
    <child link="left_lower_shoulder"/>
    <limit effort="50.0" lower="-2.147" upper="1.047" velocity="1.5"/>
    <dynamics damping="0.7" friction="0.0"/>
  </joint>
  <joint name="left_e0" type="revolute">
    <origin rpy="1.57079632679 0 1.57079632679" xyz="0.102 0 0"/>
    <axis xyz="0 0 1"/>
    <parent link="left_lower_shoulder"/>
    <child link="left_upper_elbow"/>
    <limit effort="50.0" lower="-3.05417993878" upper="3.05417993878" velocity="1.5"/>
    <dynamics damping="0.7" friction="0.0"/>
  </joint>
  <joint name="left_e0_fixed" type="fixed">
    <origin rpy="1.57079632679 0 1.57079632679" xyz="0.107 0 0"/>
    <axis xyz="0 0 1"/>
    <parent link="left_lower_shoulder"/>
    <child link="left_upper_elbow_visual"/>
  </joint>
  <joint name="left_e1" type="revolute">
    <origin rpy="-1.57079632679 -1.57079632679 0" xyz="0.069 0 0.26242"/>
    <axis xyz="0 0 1"/>
    <parent link="left_upper_elbow"/>
    <child link="left_lower_elbow"/>
    <limit effort="50.0" lower="-0.05" upper="2.618" velocity="1.5"/>
    <dynamics damping="0.7" friction="0.0"/>
  </joint>
  <joint name="left_w0" type="revolute">
    <origin rpy="1.57079632679 0 1.57079632679" xyz="0.10359 0 0"/>
    <axis xyz="0 0 1"/>
    <parent link="left_lower_elbow"/>
    <child link="left_upper_forearm"/>
    <limit effort="15.0" lower="-3.059" upper="3.059" velocity="4.0"/>
    <dynamics damping="0.7" friction="0.0"/>
  </joint>
  <joint name="left_w0_fixed" type="fixed">
    <origin rpy="1.57079632679 0 1.57079632679" xyz="0.088 0 0"/>
    <axis xyz="0 0 1"/>
    <parent link="left_lower_elbow"/>
    <child link="left_upper_forearm_visual"/>
  </joint>
  <joint name="left_w0_to_itb_fixed" type="fixed">
    <origin rpy="-1.57079632679 0 1.57079632679" xyz="-0.0565 0 0.12"/>
    <axis xyz="0 0 1"/>
    <parent link="left_upper_forearm"/>
    <child link="left_arm_itb"/>
  </joint>
  <joint name="left_w1" type="revolute">
    <origin rpy="-1.57079632679 -1.57079632679 0" xyz="0.01 0 0.2707"/>
    <axis xyz="0 0 1"/>
    <parent link="left_upper_forearm"/>
    <child link="left_lower_forearm"/>
    <limit effort="15.0" lower="-1.57079632679" upper="2.094" velocity="4.0"/>
    <dynamics damping="0.7" friction="0.0"/>
  </joint>
  <joint name="left_w2" type="revolute">
    <origin rpy="1.57079632679 0 1.57079632679" xyz="0.115975 0 0"/>
    <axis xyz="0 0 1"/>
    <parent link="left_lower_forearm"/>
    <child link="left_wrist"/>
    <limit effort="15.0" lower="-3.059" upper="3.059" velocity="4.0"/>
    <dynamics damping="0.7" friction="0.0"/>
  </joint>
  <joint name="left_hand" type="fixed">
    <origin rpy="0 0 0" xyz="0 0 0.11355"/>
    <axis xyz="0 0 1"/>
    <parent link="left_wrist"/>
    <child link="left_hand"/>
  </joint>
  <joint name="left_hand_camera" type="fixed">
    <origin rpy="0 0 -1.57079633" xyz="0.03825 0.012 0.015355"/>
    <parent link="left_hand"/>
    <child link="left_hand_camera"/>
  </joint>
  <joint name="left_hand_camera_axis" type="fixed">
    <origin rpy="0 0 0" xyz="0.03825 0.012 0.015355"/>
    <parent link="left_hand"/>
    <child link="left_hand_camera_axis"/>
  </joint>
  <joint name="left_hand_range" type="fixed">
    <origin rpy="0 -1.57079632679 -1.57079632679" xyz="0.032 -0.020245 0.0288"/>
    <parent link="left_hand"/>
    <child link="left_hand_range"/>
  </joint>
  <joint name="left_hand_accelerometer" type="fixed">
    <origin rpy="0 0 0" xyz="0.00198 0.000133 -0.0146"/>
    <parent link="left_hand"/>
    <child link="left_hand_accelerometer"/>
  </joint>
  <!-- Arguments and Defaults-->
  <link name="pedestal">
    <visual>
      <origin rpy="0 0 0" xyz="0 0 0"/>
      <geometry>
        <cylinder length="0.565" radius="0.1015"/>
        <!-- <mesh filename="package://baxter_description/meshes/base/PEDESTAL.DAE"/> -->
      </geometry>
      <material name="darkgray">
        <color rgba=".2 .2 .2 1"/>
      </material>
    </visual>
    <collision>
      <origin rpy="0 0 0" xyz="0 0 0"/>
      <geometry>
        <cylinder length="0.565" radius="0.1015"/>
        <!-- <mesh filename="package://baxter_description/meshes/base/pedestal_link_collision.DAE"/> -->
      </geometry>
    </collision>
    <inertial>
      <origin rpy="0 0 0" xyz="0 0 0"/>
      <mass value="60.86397744"/>
      <inertia ixx="5.0635929" ixy="0.00103417" ixz="0.80199628" iyy="6.08689388" iyz="0.00105311" izz="4.96191932"/>
    </inertial>
  </link>
  <joint name="pedestal_fixed" type="fixed">
    <origin rpy="0 0 0" xyz="0.0 0.0 -0.2825"/>
    <parent link="torso"/>
    <child link="pedestal"/>
  </joint>
  <!-- Base of end effector -->
  <link name="left_gripper_base">
    <visual>
      <origin rpy="-1.57079632679 3.14159265359 0" xyz="0 0 0"/>
      <geometry>
        <mesh filename="package://rethink_ee_description/meshes/electric_gripper/electric_gripper_base.DAE"/>
      </geometry>
    </visual>
    <collision>
      <origin rpy="-1.57079632679 3.14159265359 0" xyz="0.0 0.0 0"/>
      <geometry>
        <cylinder length="0.1" radius="0.029"/>
      </geometry>
      <material name="darkred">
        <color rgba=".5 .1 .1 1"/>
      </material>
    </collision>
    <inertial>
      <origin rpy="-1.57079632679 3.14159265359 0" xyz="0.0 0.0 0.0"/>
      <mass value="0.3"/>
      <inertia ixx="2e-08" ixy="0" ixz="0" iyy="3e-08" iyz="0" izz="2e-08"/>
    </inertial>
  </link>
  <link name="l_gripper_l_finger">
    <visual>
      <origin rpy="0 0 -3.14159265359" xyz="0 0 0"/>
      <geometry>
        <mesh filename="package://rethink_ee_description/meshes/electric_gripper/fingers/standard_narrow.DAE"/>
      </geometry>
    </visual>
    <collision>
      <origin rpy="0 0 -3.14159265359" xyz="0 0.01725 0.04"/>
      <geometry>
        <box size="0.01 0.0135 0.075"/>
      </geometry>
    </collision>
    <collision>
      <origin rpy="0 0 -3.14159265359" xyz="-0.005 -0.003 0.0083"/>
      <geometry>
        <box size="0.01 0.05 0.017"/>
      </geometry>
    </collision>
    <inertial>
      <origin rpy="0 0 -3.14159265359" xyz="0 0 0"/>
      <mass value="0.02"/>
      <inertia ixx="0.01" ixy="0" ixz="0" iyy="0.01" iyz="0" izz="0.01"/>
    </inertial>
  </link>
  <gazebo reference="l_gripper_l_finger">
    <mu1>1000</mu1>
    <mu2>1000</mu2>
    <fdir1>0.0 0.0 1.0</fdir1>
    <kp>1e5</kp>
    <kd>1.0</kd>
  </gazebo>
  <link name="l_gripper_l_finger_tip">
    <visual>
      <origin rpy="0 0 3.14159265359" xyz="0 0 0"/>
      <geometry>
        <mesh filename="package://rethink_ee_description/meshes/electric_gripper/fingers/basic_soft_tip.DAE"/>
      </geometry>
    </visual>
    <collision>
      <origin rpy="0 0 3.14159265359" xyz="0 -0.0045 -0.015"/>
      <geometry>
        <box size="0.016 0.007 0.037"/>
      </geometry>
    </collision>
    <inertial>
      <origin rpy="0 0 3.14159265359" xyz="0 0 0"/>
      <mass value="0.01"/>
      <inertia ixx="0.01" ixy="0" ixz="0" iyy="0.01" iyz="0" izz="0.01"/>
    </inertial>
  </link>
  <joint name="l_gripper_l_finger_tip_joint" type="fixed">
    <origin rpy="0 0 0" xyz="0.0 0.01725 0.075"/>
    <parent link="l_gripper_l_finger"/>
    <child link="l_gripper_l_finger_tip"/>
  </joint>
  <link name="l_gripper_r_finger">
    <visual>
      <origin rpy="0 0 -0.0" xyz="0 0 0"/>
      <geometry>
        <mesh filename="package://rethink_ee_description/meshes/electric_gripper/fingers/standard_narrow.DAE"/>
      </geometry>
    </visual>
    <collision>
      <origin rpy="0 0 -0.0" xyz="0 -0.01725 0.04"/>
      <geometry>
        <box size="0.01 0.0135 0.075"/>
      </geometry>
    </collision>
    <collision>
      <origin rpy="0 0 -0.0" xyz="0.005 0.003 0.0083"/>
      <geometry>
        <box size="0.01 0.05 0.017"/>
      </geometry>
    </collision>
    <inertial>
      <origin rpy="0 0 -0.0" xyz="0 0 0"/>
      <mass value="0.02"/>
      <inertia ixx="0.01" ixy="0" ixz="0" iyy="0.01" iyz="0" izz="0.01"/>
    </inertial>
  </link>
  <gazebo reference="l_gripper_r_finger">
    <mu1>1000</mu1>
    <mu2>1000</mu2>
    <fdir1>0.0 0.0 1.0</fdir1>
    <kp>1e5</kp>
    <kd>1.0</kd>
  </gazebo>
  <link name="l_gripper_r_finger_tip">
    <visual>
      <origin rpy="0 0 0.0" xyz="0 0 0"/>
      <geometry>
        <mesh filename="package://rethink_ee_description/meshes/electric_gripper/fingers/basic_soft_tip.DAE"/>
      </geometry>
    </visual>
    <collision>
      <origin rpy="0 0 0.0" xyz="0 0.0045 -0.015"/>
      <geometry>
        <box size="0.016 0.007 0.037"/>
      </geometry>
    </collision>
    <inertial>
      <origin rpy="0 0 0.0" xyz="0 0 0"/>
      <mass value="0.01"/>
      <inertia ixx="0.01" ixy="0" ixz="0" iyy="0.01" iyz="0" izz="0.01"/>
    </inertial>
  </link>
  <joint name="l_gripper_r_finger_tip_joint" type="fixed">
    <origin rpy="0 0 0" xyz="0.0 -0.01725 0.075"/>
    <parent link="l_gripper_r_finger"/>
    <child link="l_gripper_r_finger_tip"/>
  </joint>
  <!-- Electric Gripper Base Joint -->
  <joint name="left_gripper_base" type="fixed">
    <origin rpy="0 0 0" xyz="0 0 0.025"/>
    <parent link="left_hand"/>
    <child link="left_gripper_base"/>
  </joint>
  <!-- Electric Gripper Tip joint -->
  <joint name="left_endpoint" type="fixed">
    <origin rpy="0 0 0" xyz="0 0 0.095"/>
    <parent link="left_gripper_base"/>
    <child link="left_gripper"/>
  </joint>
  <!-- Electric Gripper Tip link -->
  <link name="left_gripper">
    <inertial>
      <origin rpy="0 0 0" xyz="0 0 0"/>
      <mass value="0.0001"/>
      <inertia ixx="0" ixy="0" ixz="0" iyy="0" iyz="0" izz="0.0"/>
    </inertial>
  </link>
  <joint name="l_gripper_l_finger_joint" type="prismatic">
    <origin rpy="0 0 0" xyz="0.0 -0.011 0.02"/>
    <axis xyz="0 1 0"/>
    <parent link="left_gripper_base"/>
    <child link="l_gripper_l_finger"/>
    <limit effort="20.0" lower="0.0" upper="0.020833" velocity="5.0"/>
    <dynamics damping="0.7" friction="0.0"/>
  </joint>
  <joint name="l_gripper_r_finger_joint" type="prismatic">
    <origin rpy="0 0 0" xyz="0.0 0.011 0.02"/>
    <axis xyz="0 1 0"/>
    <parent link="left_gripper_base"/>
    <child link="l_gripper_r_finger"/>
    <limit effort="20.0" lower="-0.020833" upper="0.0" velocity="5.0"/>
    <mimic joint="l_gripper_l_finger_joint" multiplier="-1.0"/>
    <dynamics damping="0.7" friction="0.0"/>
  </joint>
  <transmission name="gripper_left1">
    <type>transmission_interface/SimpleTransmission</type>
    <joint name="l_gripper_r_finger_joint">
      <hardwareInterface>hardware_interface/EffortJointInterface</hardwareInterface>
    </joint>
    <actuator name="gripper_l1_motor1">
      <hardwareInterface>hardware_interface/EffortJointInterface</hardwareInterface>
      <mechanicalReduction>1</mechanicalReduction>
    </actuator>
  </transmission>
  <transmission name="gripper_left2">
    <type>transmission_interface/SimpleTransmission</type>
    <joint name="l_gripper_l_finger_joint">
      <hardwareInterface>hardware_interface/EffortJointInterface</hardwareInterface>
    </joint>
    <actuator name="gripper_l1_motor2">
      <hardwareInterface>hardware_interface/EffortJointInterface</hardwareInterface>
      <mechanicalReduction>1</mechanicalReduction>
    </actuator>
  </transmission>
  <gazebo reference="l_gripper_r_finger_joint">
    <implicitSpringDamper>1</implicitSpringDamper>
  </gazebo>
  <gazebo reference="l_gripper_l_finger_joint">
    <implicitSpringDamper>1</implicitSpringDamper>
  </gazebo>
  <!-- Base of end effector -->
  <link name="right_gripper_base">
    <visual>
      <origin rpy="-1.57079632679 3.14159265359 0" xyz="0 0 0"/>
      <geometry>
        <mesh filename="package://rethink_ee_description/meshes/electric_gripper/electric_gripper_base.DAE"/>
      </geometry>
    </visual>
    <collision>
      <origin rpy="-1.57079632679 3.14159265359 0" xyz="0.0 0.0 0"/>
      <geometry>
        <cylinder length="0.1" radius="0.029"/>
      </geometry>
      <material name="darkred">
        <color rgba=".5 .1 .1 1"/>
      </material>
    </collision>
    <inertial>
      <origin rpy="-1.57079632679 3.14159265359 0" xyz="0.0 0.0 0.0"/>
      <mass value="0.3"/>
      <inertia ixx="2e-08" ixy="0" ixz="0" iyy="3e-08" iyz="0" izz="2e-08"/>
    </inertial>
  </link>
  <link name="r_gripper_l_finger">
    <visual>
      <origin rpy="0 0 -3.14159265359" xyz="0 0 0"/>
      <geometry>
        <mesh filename="package://rethink_ee_description/meshes/electric_gripper/fingers/extended_wide.DAE"/>
      </geometry>
    </visual>
    <collision>
      <origin rpy="0 0 -3.14159265359" xyz="0 0.05503 0.0615"/>
      <geometry>
        <box size="0.01 0.0135 0.1127"/>
      </geometry>
    </collision>
    <collision>
      <origin rpy="0 0 -3.14159265359" xyz="-0.005 0.016 0.0083"/>
      <geometry>
        <box size="0.01 0.08778 0.017"/>
      </geometry>
    </collision>
    <inertial>
      <origin rpy="0 0 -3.14159265359" xyz="0 0 0"/>
      <mass value="0.02"/>
      <inertia ixx="0.01" ixy="0" ixz="0" iyy="0.01" iyz="0" izz="0.01"/>
    </inertial>
  </link>
  <gazebo reference="r_gripper_l_finger">
    <mu1>1000</mu1>
    <mu2>1000</mu2>
    <fdir1>0.0 0.0 1.0</fdir1>
    <kp>1e5</kp>
    <kd>1.0</kd>
  </gazebo>
  <link name="r_gripper_l_finger_tip">
    <visual>
      <origin rpy="0 0 3.14159265359" xyz="0 0 0"/>
      <geometry>
        <mesh filename="package://rethink_ee_description/meshes/electric_gripper/fingers/paddle_tip.DAE"/>
      </geometry>
    </visual>
    <collision>
      <origin rpy="0 0 3.14159265359" xyz="0 -0.0045 -0.015"/>
      <geometry>
        <box size="0.042 0.0065 0.037"/>
      </geometry>
    </collision>
    <inertial>
      <origin rpy="0 0 3.14159265359" xyz="0 0 0"/>
      <mass value="0.01"/>
      <inertia ixx="0.01" ixy="0" ixz="0" iyy="0.01" iyz="0" izz="0.01"/>
    </inertial>
  </link>
  <joint name="r_gripper_l_finger_tip_joint" type="fixed">
    <origin rpy="0 0 0" xyz="0.0 0.05503 0.1127"/>
    <parent link="r_gripper_l_finger"/>
    <child link="r_gripper_l_finger_tip"/>
  </joint>
  <link name="r_gripper_r_finger">
    <visual>
      <origin rpy="0 0 -0.0" xyz="0 0 0"/>
      <geometry>
        <mesh filename="package://rethink_ee_description/meshes/electric_gripper/fingers/extended_wide.DAE"/>
      </geometry>
    </visual>
    <collision>
      <origin rpy="0 0 -0.0" xyz="0 -0.05503 0.0615"/>
      <geometry>
        <box size="0.01 0.0135 0.1127"/>
      </geometry>
    </collision>
    <collision>
      <origin rpy="0 0 -0.0" xyz="0.005 -0.016 0.0083"/>
      <geometry>
        <box size="0.01 0.08778 0.017"/>
      </geometry>
    </collision>
    <inertial>
      <origin rpy="0 0 -0.0" xyz="0 0 0"/>
      <mass value="0.02"/>
      <inertia ixx="0.01" ixy="0" ixz="0" iyy="0.01" iyz="0" izz="0.01"/>
    </inertial>
  </link>
  <gazebo reference="r_gripper_r_finger">
    <mu1>1000</mu1>
    <mu2>1000</mu2>
    <fdir1>0.0 0.0 1.0</fdir1>
    <kp>1e5</kp>
    <kd>1.0</kd>
  </gazebo>
  <link name="r_gripper_r_finger_tip">
    <visual>
      <origin rpy="0 0 0.0" xyz="0 0 0"/>
      <geometry>
        <mesh filename="package://rethink_ee_description/meshes/electric_gripper/fingers/paddle_tip.DAE"/>
      </geometry>
    </visual>
    <collision>
      <origin rpy="0 0 0.0" xyz="0 0.0045 -0.015"/>
      <geometry>
        <box size="0.042 0.0065 0.037"/>
      </geometry>
    </collision>
    <inertial>
      <origin rpy="0 0 0.0" xyz="0 0 0"/>
      <mass value="0.01"/>
      <inertia ixx="0.01" ixy="0" ixz="0" iyy="0.01" iyz="0" izz="0.01"/>
    </inertial>
  </link>
  <joint name="r_gripper_r_finger_tip_joint" type="fixed">
    <origin rpy="0 0 0" xyz="0.0 -0.05503 0.1127"/>
    <parent link="r_gripper_r_finger"/>
    <child link="r_gripper_r_finger_tip"/>
  </joint>
  <!-- Electric Gripper Base Joint -->
  <joint name="right_gripper_base" type="fixed">
    <origin rpy="0 0 0" xyz="0 0 0.025"/>
    <parent link="right_hand"/>
    <child link="right_gripper_base"/>
  </joint>
  <!-- Electric Gripper Tip joint -->
  <joint name="right_endpoint" type="fixed">
    <origin rpy="0 0 0" xyz="0 0 0.1327"/>
    <parent link="right_gripper_base"/>
    <child link="right_gripper"/>
  </joint>
  <!-- Electric Gripper Tip link -->
  <link name="right_gripper">
    <inertial>
      <origin rpy="0 0 0" xyz="0 0 0"/>
      <mass value="0.0001"/>
      <inertia ixx="0" ixy="0" ixz="0" iyy="0" iyz="0" izz="0.0"/>
    </inertial>
  </link>
  <joint name="r_gripper_l_finger_joint" type="prismatic">
    <origin rpy="0 0 0" xyz="0.0 0.0175 0.02"/>
    <axis xyz="0 1 0"/>
    <parent link="right_gripper_base"/>
    <child link="r_gripper_l_finger"/>
    <limit effort="20.0" lower="0.0" upper="0.020833" velocity="5.0"/>
    <dynamics damping="0.7" friction="0.0"/>
  </joint>
  <joint name="r_gripper_r_finger_joint" type="prismatic">
    <origin rpy="0 0 0" xyz="0.0 -0.0175 0.02"/>
    <axis xyz="0 1 0"/>
    <parent link="right_gripper_base"/>
    <child link="r_gripper_r_finger"/>
    <limit effort="20.0" lower="-0.020833" upper="0.0" velocity="5.0"/>
    <mimic joint="r_gripper_l_finger_joint" multiplier="-1.0"/>
    <dynamics damping="0.7" friction="0.0"/>
  </joint>
  <transmission name="gripper_right1">
    <type>transmission_interface/SimpleTransmission</type>
    <joint name="r_gripper_r_finger_joint">
      <hardwareInterface>hardware_interface/EffortJointInterface</hardwareInterface>
    </joint>
    <actuator name="gripper_r1_motor1">
      <hardwareInterface>hardware_interface/EffortJointInterface</hardwareInterface>
      <mechanicalReduction>1</mechanicalReduction>
    </actuator>
  </transmission>
  <transmission name="gripper_right2">
    <type>transmission_interface/SimpleTransmission</type>
    <joint name="r_gripper_l_finger_joint">
      <hardwareInterface>hardware_interface/EffortJointInterface</hardwareInterface>
    </joint>
    <actuator name="gripper_r1_motor2">
      <hardwareInterface>hardware_interface/EffortJointInterface</hardwareInterface>
      <mechanicalReduction>1</mechanicalReduction>
    </actuator>
  </transmission>
  <gazebo reference="r_gripper_r_finger_joint">
    <implicitSpringDamper>1</implicitSpringDamper>
  </gazebo>
  <gazebo reference="r_gripper_l_finger_joint">
    <implicitSpringDamper>1</implicitSpringDamper>
  </gazebo>
  <!-- Link Baxter and Ridgeback-->
  <joint name="ridgeback_base_to_baxter" type="fixed">
    <origin rpy="0 0 0" xyz="0.2 0 0.85"/>
    <parent link="chassis_link"/>
    <child link="base"/>
  </joint>
</robot>
